Workbook
Name NativeTimeline_UpdatedDate: #N/A
Name Slicer_Country: #N/A
Name Slicer_SourceSystem: #N/A
Name Slicer_Status: #N/A
Name Slicer_YearMonth: #N/A

Sheet RawData
A1: Address | B1: PostalCode | C1: Phone | D1: Country | E1: CityInput | F1: PropertyID | G1: Status | H1: UpdatedDate | I1: SourceSystem | J1: Notes
A2: FranceToulouse | B2: 32599 | C2: +17-315833500 | D2: France | E2: Toulouse | F2: PROP00001 | G2: Active | H2: 45482 | I2: ServiceNow | J2: Check postal code
A3: Lyon, Donald Cove 35, France | B3: 89197 | C3: +80-319837636 | D3: France | E3: Lyon | F3: PROP00002 | G3: Inactive | H3: 45242 | I3: Planon | J3: Pending validation
A4: UKLeeds, UK | B4: 4406 | C4: +9-597990383 | D4: UK | E4: Leeds | F4: PROP00003 | G4: Inactive | H4: 45259 | I4: Planon
A5: ToulouseJeffery Parkways231, France | B5: 79408 | C5: +41-562032557 | D5: France | E5: Toulouse | F5: PROP00004 | G5: Inactive | H5: 45406 | I5: MDG
A6: AdelaideAnna Stravenue73, Australia | B6: 85682 | C6: +58-662081724 | D6: Australia | E6: Adelaide | F6: PROP00005 | G6: Active | H6: 44973 | I6: Salesforce | J6: Check postal code
A7: USA, Phoenix | B7: 36964 | C7: +75-783458296 | D7: USA | E7: Phoenix | F7: PROP00006 | G7: Inactive | H7: 45086 | I7: Planon | J7: Check postal code
A8: Katherine Estate 93, Germany, Cologne | B8: 92007 | C8: +24-457327975 | D8: Germany | E8: Cologne | F8: PROP00007 | G8: Active | H8: 45240 | I8: ServiceNow | J8: Imported from legacy system
A9: Peterson Drives 204, Germany, Cologne | B9: 28722 | C9: +49-576610421 | D9: Germany | E9: Cologne | F9: PROP00008 | G9: Active | H9: 44972 | I9: SAP | J9: Imported from legacy system
A10: SpainBarcelona, Spain | B10: 13177 | C10: +34-805788258 | D10: Spain | E10: Barcelona | F10: PROP00009 | G10: Inactive | H10: 45573 | I10: SAP | J10: Imported from legacy system
A11: Abbott Rapids 298, Brazil, Brasília | B11: 35172 | C11: +74-707015923 | D11: Brazil | E11: Brasília | F11: PROP00010 | G11: Active | H11: 45768 | I11: MDG | J11: Check postal code
A12: Australia, Perth | B12: 16862 | C12: +19-563762604 | D12: Australia | E12: Perth | F12: PROP00011 | G12: Active | H12: 44924 | I12: SAP | J12: Check postal code
A13: CanadaOttawa | B13: 82898 | C13: +76-641811982 | D13: Canada | E13: Ottawa | F13: PROP00012 | G13: Active | H13: 45943 | I13: Salesforce
A14: USALos AngelesRay Squares47 | B14: 9617 | C14: +28-603554893 | D14: USA | E14: Los Angeles | F14: PROP00013 | G14: Active | H14: 45465 | I14: SAP | J14: Verified
A15: Donna Trail 183, UK, Leeds | B15: 38431 | C15: +43-971324654 | D15: UK | E15: Leeds | F15: PROP00014 | G15: Inactive | H15: 45344 | I15: MDG
A16: ItalyRome | B16: 13739 | C16: +85-846405798 | D16: Italy | E16: Rome | F16: PROP00015 | G16: Inactive | H16: 45347 | I16: Planon
A17: BrazilSalvador, Brazil | B17: 48320 | C17: +27-184834988 | D17: Brazil | E17: Salvador | F17: PROP00016 | G17: Inactive | H17: 45771 | I17: MDG
A18: CanadaCalgary, Canada | B18: 88342 | C18: +28-803880368 | D18: Canada | E18: Calgary | F18: PROP00017 | G18: Active | H18: 45494 | I18: Salesforce | J18: Needs review
A19: UK, Birmingham | B19: 85440 | C19: +41-132506172 | D19: UK | E19: Birmingham | F19: PROP00018 | G19: Inactive | H19: 45832 | I19: SAP | J19: Pending validation
A20: BrasíliaChelsea Extension100, Brazil | B20: 70511 | C20: +67-358446679 | D20: Brazil | E20: Brasília | F20: PROP00019 | G20: Active | H20: 45430 | I20: Salesforce
A21: Canada, Calgary, Frank Light 65 | B21: 35883 | C21: +42-523118317 | D21: Canada | E21: Calgary | F21: PROP00020 | G21: Active | H21: 45200 | I21: Salesforce | J21: Imported from legacy system
A22: Chicago, Gabrielle Ville 211, USA | B22: 7832 | C22: +92-984554908 | D22: USA | E22: Chicago | F22: PROP00021 | G22: Active | H22: 45595 | I22: MDG
A23: GermanyMunichLydia Valley281 | B23: 41848 | C23: +48-719462908 | D23: Germany | E23: Munich | F23: PROP00022 | G23: Active | H23: 45965 | I23: MDG
A24: GermanyCologne | B24: 74842 | C24: +65-946225910 | D24: Germany | E24: Cologne | F24: PROP00023 | G24: Active | H24: 45742 | I24: ServiceNow
A25: ItalyFlorenceLewis Parks198 | B25: 52357 | C25: +69-262946533 | D25: Italy | E25: Florence | F25: PROP00024 | G25: Inactive | H25: 44943 | I25: Planon | J25: Imported from legacy system
A26: Thomas Dam 63, France, Marseille | B26: 32826 | C26: +87-969160078 | D26: France | E26: Marseille | F26: PROP00025 | G26: Active | H26: 45674 | I26: MDG
A27: Burgess Meadow 171, Australia, Melbourne | B27: 76985 | C27: +91-598066265 | D27: Australia | E27: Melbourne | F27: PROP00026 | G27: Inactive | H27: 45468 | I27: ServiceNow
A28: SydneyCox Dam230, Australia | B28: 67285 | C28: +26-438045007 | D28: Australia | E28: Sydney | F28: PROP00027 | G28: Active | H28: 45326 | I28: SAP
A29: LeedsDavis Causeway293, UK | B29: 14872 | C29: +52-806505381 | D29: UK | E29: Leeds | F29: PROP00028 | G29: Inactive | H29: 45864 | I29: SAP | J29: Imported from legacy system
A30: Courtney Turnpike165, Bordeaux, France | B30: 89693 | C30: +61-184724290 | D30: France | E30: Bordeaux | F30: PROP00029 | G30: Active | H30: 45767 | I30: Salesforce | J30: Check postal code
A31: Germany, Cologne | B31: 50520 | C31: +84-507576334 | D31: Germany | E31: Cologne | F31: PROP00030 | G31: Inactive | H31: 45909 | I31: MDG
A32: Canada, Ottawa | B32: 2005 | C32: +13-132980297 | D32: Canada | E32: Ottawa | F32: PROP00031 | G32: Inactive | H32: 45201 | I32: Salesforce
A33: UKBirmingham, UK | B33: 98920 | C33: +36-618266385 | D33: UK | E33: Birmingham | F33: PROP00032 | G33: Active | H33: 45225 | I33: ServiceNow | J33: Needs review
A34: MunichMack Junctions229, Germany | B34: 15122 | C34: +35-763070022 | D34: Germany | E34: Munich | F34: PROP00033 | G34: Active | H34: 45132 | I34: Salesforce | J34: Imported from legacy system
A35: Graham Motorway 9, Rio de Janeiro | B35: 926 | C35: +5-377335239 | D35: Brazil | E35: Rio de Janeiro | F35: PROP00034 | G35: Active | H35: 45662 | I35: SAP | J35: Check postal code
A36: UK, Manchester, Stanton Track 112 | B36: 23917 | C36: +82-366448994 | D36: UK | E36: Manchester | F36: PROP00035 | G36: Active | H36: 45181 | I36: SAP
A37: Australia, Brisbane, Monica Hills 117 | B37: 84249 | C37: +8-137243090 | D37: Australia | E37: Brisbane | F37: PROP00036 | G37: Active | H37: 45219 | I37: Salesforce
A38: France, Paris, Eric Track 273 | B38: 21675 | C38: +7-834425624 | D38: France | E38: Paris | F38: PROP00037 | G38: Inactive | H38: 45643 | I38: Planon
A39: SydneyCarol Overpass103, Australia | B39: 3053 | C39: +54-303640140 | D39: Australia | E39: Sydney | F39: PROP00038 | G39: Inactive | H39: 45939 | I39: SAP | J39: Pending validation
A40: SapporoSarah Wells54, Japan | B40: 40807 | C40: +15-618313077 | D40: Japan | E40: Sapporo | F40: PROP00039 | G40: Inactive | H40: 45339 | I40: ServiceNow | J40: Needs review
...

Sheet CleanedData
A1: Address | B1: PostalCode | C1: Phone | D1: Country | E1: CityInput | F1: PropertyID | G1: Status | H1: UpdatedDate | I1: SourceSystem | J1: Notes | K1: PostalCode_OK | L1: Phone_OK | M1: Street_extracted | N1: MissingStreet | O1: City_extracted | P1: City_Match | Q1: AnyError | R1: ErrorCount
A2: FranceToulouse | B2: 32599 | C2: +17-315833500 | D2: France | E2: Toulouse | F2: PROP00001 | G2: Active | H2: 45482 | I2: ServiceNow | J2: Check postal code | K2: OK | L2: OK | N2: MISSING | O2: Toulouse | P2: MATCH | Q2: ERROR | R2: 1
A3: Lyon, Donald Cove 35, France | B3: 89197 | C3: +80-319837636 | D3: France | E3: Lyon | F3: PROP00002 | G3: Inactive | H3: 45242 | I3: Planon | J3: Pending validation | K3: OK | L3: OK | M3: Donald Cove 35 | N3: OK | O3: Lyon | P3: MATCH | Q3: OK | R3: 0
A4: UKLeeds, UK | B4: 4406 | C4: +9-597990383 | D4: UK | E4: Leeds | F4: PROP00003 | G4: Inactive | H4: 45259 | I4: Planon | K4: OK | L4: OK | M4: UK | N4: OK | O4: Leeds | P4: MATCH | Q4: OK | R4: 0
A5: ToulouseJeffery Parkways231, France | B5: 79408 | C5: +41-562032557 | D5: France | E5: Toulouse | F5: PROP00004 | G5: Inactive | H5: 45406 | I5: MDG | K5: OK | L5: OK | M5: ToulouseJeffery Parkways231 | N5: OK | O5: Toulouse | P5: MATCH | Q5: OK | R5: 0
A6: AdelaideAnna Stravenue73, Australia | B6: 85682 | C6: +58-662081724 | D6: Australia | E6: Adelaide | F6: PROP00005 | G6: Active | H6: 44973 | I6: Salesforce | J6: Check postal code | K6: OK | L6: OK | M6: AdelaideAnna Stravenue73 | N6: OK | O6: Adelaide | P6: MATCH | Q6: OK | R6: 0
A7: USA, Phoenix | B7: 36964 | C7: +75-783458296 | D7: USA | E7: Phoenix | F7: PROP00006 | G7: Inactive | H7: 45086 | I7: Planon | J7: Check postal code | K7: OK | L7: OK | M7: Phoenix | N7: OK | O7: Phoenix | P7: MATCH | Q7: OK | R7: 0
A8: Katherine Estate 93, Germany, Cologne | B8: 92007 | C8: +24-457327975 | D8: Germany | E8: Cologne | F8: PROP00007 | G8: Active | H8: 45240 | I8: ServiceNow | J8: Imported from legacy system | K8: OK | L8: OK | M8: Katherine Estate 93 | N8: OK | O8: Cologne | P8: MATCH | Q8: OK | R8: 0
A9: Peterson Drives 204, Germany, Cologne | B9: 28722 | C9: +49-576610421 | D9: Germany | E9: Cologne | F9: PROP00008 | G9: Active | H9: 44972 | I9: SAP | J9: Imported from legacy system | K9: OK | L9: OK | M9: Peterson Drives 204 | N9: OK | O9: Cologne | P9: MATCH | Q9: OK | R9: 0
A10: SpainBarcelona, Spain | B10: 13177 | C10: +34-805788258 | D10: Spain | E10: Barcelona | F10: PROP00009 | G10: Inactive | H10: 45573 | I10: SAP | J10: Imported from legacy system | K10: OK | L10: OK | M10: Spain | N10: OK | O10: Barcelona | P10: MATCH | Q10: OK | R10: 0
A11: Abbott Rapids 298, Brazil, Brasília | B11: 35172 | C11: +74-707015923 | D11: Brazil | E11: Brasília | F11: PROP00010 | G11: Active | H11: 45768 | I11: MDG | J11: Check postal code | K11: OK | L11: OK | M11: Abbott Rapids 298 | N11: OK | O11: Brasília | P11: MATCH | Q11: OK | R11: 0
A12: Australia, Perth | B12: 16862 | C12: +19-563762604 | D12: Australia | E12: Perth | F12: PROP00011 | G12: Active | H12: 44924 | I12: SAP | J12: Check postal code | K12: OK | L12: OK | M12: Perth | N12: OK | O12: Perth | P12: MATCH | Q12: OK | R12: 0
A13: CanadaOttawa | B13: 82898 | C13: +76-641811982 | D13: Canada | E13: Ottawa | F13: PROP00012 | G13: Active | H13: 45943 | I13: Salesforce | K13: OK | L13: OK | N13: MISSING | O13: Ottawa | P13: MATCH | Q13: ERROR | R13: 1
A14: USALos AngelesRay Squares47 | B14: 9617 | C14: +28-603554893 | D14: USA | E14: Los Angeles | F14: PROP00013 | G14: Active | H14: 45465 | I14: SAP | J14: Verified | K14: OK | L14: OK | M14: USALos AngelesRay Squares47 | N14: OK | O14: Los Angeles | P14: MATCH | Q14: OK | R14: 0
A15: Donna Trail 183, UK, Leeds | B15: 38431 | C15: +43-971324654 | D15: UK | E15: Leeds | F15: PROP00014 | G15: Inactive | H15: 45344 | I15: MDG | K15: OK | L15: OK | M15: Donna Trail 183 | N15: OK | O15: Leeds | P15: MATCH | Q15: OK | R15: 0
A16: ItalyRome | B16: 13739 | C16: +85-846405798 | D16: Italy | E16: Rome | F16: PROP00015 | G16: Inactive | H16: 45347 | I16: Planon | K16: OK | L16: OK | N16: MISSING | O16: Rome | P16: MATCH | Q16: ERROR | R16: 1
A17: BrazilSalvador, Brazil | B17: 48320 | C17: +27-184834988 | D17: Brazil | E17: Salvador | F17: PROP00016 | G17: Inactive | H17: 45771 | I17: MDG | K17: OK | L17: OK | M17: Brazil | N17: OK | O17: Salvador | P17: MATCH | Q17: OK | R17: 0
A18: CanadaCalgary, Canada | B18: 88342 | C18: +28-803880368 | D18: Canada | E18: Calgary | F18: PROP00017 | G18: Active | H18: 45494 | I18: Salesforce | J18: Needs review | K18: OK | L18: OK | M18: Canada | N18: OK | O18: Calgary | P18: MATCH | Q18: OK | R18: 0
A19: UK, Birmingham | B19: 85440 | C19: +41-132506172 | D19: UK | E19: Birmingham | F19: PROP00018 | G19: Inactive | H19: 45832 | I19: SAP | J19: Pending validation | K19: OK | L19: OK | M19: Birmingham | N19: OK | O19: Birmingham | P19: MATCH | Q19: OK | R19: 0
A20: BrasíliaChelsea Extension100, Brazil | B20: 70511 | C20: +67-358446679 | D20: Brazil | E20: Brasília | F20: PROP00019 | G20: Active | H20: 45430 | I20: Salesforce | K20: OK | L20: OK | M20: BrasíliaChelsea Extension100 | N20: OK | O20: Brasília | P20: MATCH | Q20: OK | R20: 0
A21: Canada, Calgary, Frank Light 65 | B21: 35883 | C21: +42-523118317 | D21: Canada | E21: Calgary | F21: PROP00020 | G21: Active | H21: 45200 | I21: Salesforce | J21: Imported from legacy system | K21: OK | L21: OK | M21: Frank Light 65 | N21: OK | O21: Calgary | P21: MATCH | Q21: OK | R21: 0
A22: Chicago, Gabrielle Ville 211, USA | B22: 7832 | C22: +92-984554908 | D22: USA | E22: Chicago | F22: PROP00021 | G22: Active | H22: 45595 | I22: MDG | K22: OK | L22: OK | M22: Gabrielle Ville 211 | N22: OK | O22: Chicago | P22: MATCH | Q22: OK | R22: 0
A23: GermanyMunichLydia Valley281 | B23: 41848 | C23: +48-719462908 | D23: Germany | E23: Munich | F23: PROP00022 | G23: Active | H23: 45965 | I23: MDG | K23: OK | L23: OK | M23: GermanyMunichLydia Valley281 | N23: OK | O23: Munich | P23: MATCH | Q23: OK | R23: 0
A24: GermanyCologne | B24: 74842 | C24: +65-946225910 | D24: Germany | E24: Cologne | F24: PROP00023 | G24: Active | H24: 45742 | I24: ServiceNow | K24: OK | L24: OK | N24: MISSING | O24: Cologne | P24: MATCH | Q24: ERROR | R24: 1
A25: ItalyFlorenceLewis Parks198 | B25: 52357 | C25: +69-262946533 | D25: Italy | E25: Florence | F25: PROP00024 | G25: Inactive | H25: 44943 | I25: Planon | J25: Imported from legacy system | K25: OK | L25: OK | M25: ItalyFlorenceLewis Parks198 | N25: OK | O25: Florence | P25: MATCH | Q25: OK | R25: 0
A26: Thomas Dam 63, France, Marseille | B26: 32826 | C26: +87-969160078 | D26: France | E26: Marseille | F26: PROP00025 | G26: Active | H26: 45674 | I26: MDG | K26: OK | L26: OK | M26: Thomas Dam 63 | N26: OK | O26: Marseille | P26: MATCH | Q26: OK | R26: 0
A27: Burgess Meadow 171, Australia, Melbourne | B27: 76985 | C27: +91-598066265 | D27: Australia | E27: Melbourne | F27: PROP00026 | G27: Inactive | H27: 45468 | I27: ServiceNow | K27: OK | L27: OK | M27: Burgess Meadow 171 | N27: OK | O27: Melbourne | P27: MATCH | Q27: OK | R27: 0
A28: SydneyCox Dam230, Australia | B28: 67285 | C28: +26-438045007 | D28: Australia | E28: Sydney | F28: PROP00027 | G28: Active | H28: 45326 | I28: SAP | K28: OK | L28: OK | M28: SydneyCox Dam230 | N28: OK | O28: Sydney | P28: MATCH | Q28: OK | R28: 0
A29: LeedsDavis Causeway293, UK | B29: 14872 | C29: +52-806505381 | D29: UK | E29: Leeds | F29: PROP00028 | G29: Inactive | H29: 45864 | I29: SAP | J29: Imported from legacy system | K29: OK | L29: OK | M29: LeedsDavis Causeway293 | N29: OK | O29: Leeds | P29: MATCH | Q29: OK | R29: 0
A30: Courtney Turnpike165, Bordeaux, France | B30: 89693 | C30: +61-184724290 | D30: France | E30: Bordeaux | F30: PROP00029 | G30: Active | H30: 45767 | I30: Salesforce | J30: Check postal code | K30: OK | L30: OK | M30: Courtney Turnpike165 | N30: OK | O30: Bordeaux | P30: MATCH | Q30: OK | R30: 0
A31: Germany, Cologne | B31: 50520 | C31: +84-507576334 | D31: Germany | E31: Cologne | F31: PROP00030 | G31: Inactive | H31: 45909 | I31: MDG | K31: OK | L31: OK | M31: Cologne | N31: OK | O31: Cologne | P31: MATCH | Q31: OK | R31: 0
A32: Canada, Ottawa | B32: 2005 | C32: +13-132980297 | D32: Canada | E32: Ottawa | F32: PROP00031 | G32: Inactive | H32: 45201 | I32: Salesforce | K32: OK | L32: OK | M32: Ottawa | N32: OK | O32: Ottawa | P32: MATCH | Q32: OK | R32: 0
A33: UKBirmingham, UK | B33: 98920 | C33: +36-618266385 | D33: UK | E33: Birmingham | F33: PROP00032 | G33: Active | H33: 45225 | I33: ServiceNow | J33: Needs review | K33: OK | L33: OK | M33: UK | N33: OK | O33: Birmingham | P33: MATCH | Q33: OK | R33: 0
A34: MunichMack Junctions229, Germany | B34: 15122 | C34: +35-763070022 | D34: Germany | E34: Munich | F34: PROP00033 | G34: Active | H34: 45132 | I34: Salesforce | J34: Imported from legacy system | K34: OK | L34: OK | M34: MunichMack Junctions229 | N34: OK | O34: Munich | P34: MATCH | Q34: OK | R34: 0
A35: Graham Motorway 9, Rio de Janeiro | B35: 926 | C35: +5-377335239 | D35: Brazil | E35: Rio de Janeiro | F35: PROP00034 | G35: Active | H35: 45662 | I35: SAP | J35: Check postal code | K35: OK | L35: OK | M35: Graham Motorway 9 | N35: OK | O35: Rio de Janeiro | P35: MATCH | Q35: OK | R35: 0
A36: UK, Manchester, Stanton Track 112 | B36: 23917 | C36: +82-366448994 | D36: UK | E36: Manchester | F36: PROP00035 | G36: Active | H36: 45181 | I36: SAP | K36: OK | L36: OK | M36: Stanton Track 112 | N36: OK | O36: Manchester | P36: MATCH | Q36: OK | R36: 0
A37: Australia, Brisbane, Monica Hills 117 | B37: 84249 | C37: +8-137243090 | D37: Australia | E37: Brisbane | F37: PROP00036 | G37: Active | H37: 45219 | I37: Salesforce | K37: OK | L37: OK | M37: Monica Hills 117 | N37: OK | O37: Brisbane | P37: MATCH | Q37: OK | R37: 0
A38: France, Paris, Eric Track 273 | B38: 21675 | C38: +7-834425624 | D38: France | E38: Paris | F38: PROP00037 | G38: Inactive | H38: 45643 | I38: Planon | K38: OK | L38: OK | M38: Eric Track 273 | N38: OK | O38: Paris | P38: MATCH | Q38: OK | R38: 0
A39: SydneyCarol Overpass103, Australia | B39: 3053 | C39: +54-303640140 | D39: Australia | E39: Sydney | F39: PROP00038 | G39: Inactive | H39: 45939 | I39: SAP | J39: Pending validation | K39: OK | L39: OK | M39: SydneyCarol Overpass103 | N39: OK | O39: Sydney | P39: MATCH | Q39: OK | R39: 0
A40: SapporoSarah Wells54, Japan | B40: 40807 | C40: +15-618313077 | D40: Japan | E40: Sapporo | F40: PROP00039 | G40: Inactive | H40: 45339 | I40: ServiceNow | J40: Needs review | K40: OK | L40: OK | M40: SapporoSarah Wells54 | N40: OK | O40: Sapporo | P40: MATCH | Q40: OK | R40: 0
...

Sheet Checks
A1: PropertyID | B1: Address | C1: Country | D1: CityInput | E1: City_extracted | F1: Street_extracted | G1: PostalCode | H1: Phone | I1: Status | J1: UpdatedDate | K1: MissingStreet | L1: PostalCode_OK | M1: Phone_OK | N1: City_Match | O1: AnyError | P1: ErrorCount | Q1: YearMonth | R1: SourceSystem | S1: IsError | T1: IsMissingStreet | U1: ErrorType
A2: =CleanedData!F2 -> PROP00001 | B2: =CleanedData!A2 -> FranceToulouse | C2: =CleanedData!D2 -> France | D2: =CleanedData!E2 -> Toulouse | E2: =CleanedData!O2 -> Toulouse | F2: =CleanedData!M2 | G2: =CleanedData!B2 -> 32599 | H2: =CleanedData!C2 -> +17-315833500 | I2: =CleanedData!G2 -> Active | J2: =CleanedData!H2 -> 45482 | K2: =IF(TRIM(F2)="","MISSING","OK") -> MISSING | L2: =IF(LEN(TRIM(G2))<3,"INVALID","OK") -> OK | M2: =IF(LEN(SUBSTITUTE(SUBSTITUTE(H2," ",""),"-",""))>=7,"OK","INVALID") -> OK | N2: =IF(E2="","NO_EXTRACT", IF(LOWER(TRIM(E2))=LOWER(TRIM(D2)),"MATCH","CHECK")) -> MATCH | O2: =IF(OR(K2="MISSING",L2="INVALID",M2="INVALID"),"ERROR","OK") -> ERROR | P2: =(K2="MISSING")*1 + (L2="INVALID")*1 + (M2="INVALID")*1 -> 1 | Q2: =YEAR(J2) & "-" & TEXT(MONTH(J2),"00") -> 2024-07 | R2: ServiceNow | S2: =IF(tblChecks[[#This Row],[AnyError]]="ERROR",1,0) -> 1 | T2: =IF(tblChecks[[#This Row],[MissingStreet]]="MISSING",1,0) -> 1 | U2: =IF(K2="MISSING","MissingStreet", IF(L2="INVALID","PostalCode_INVALID", IF(M2="INVALID","Phone_INVALID","OK"))) -> MissingStreet
A3: =CleanedData!F3 -> PROP00002 | B3: =CleanedData!A3 -> Lyon, Donald Cove 35, France | C3: =CleanedData!D3 -> France | D3: =CleanedData!E3 -> Lyon | E3: =CleanedData!O3 -> Lyon | F3: =CleanedData!M3 -> Donald Cove 35 | G3: =CleanedData!B3 -> 89197 | H3: =CleanedData!C3 -> +80-319837636 | I3: =CleanedData!G3 -> Inactive | J3: =CleanedData!H3 -> 45242 | K3: =IF(TRIM(F3)="","MISSING","OK") -> OK | L3: =IF(LEN(TRIM(G3))<3,"INVALID","OK") -> OK | M3: =IF(LEN(SUBSTITUTE(SUBSTITUTE(H3," ",""),"-",""))>=7,"OK","INVALID") -> OK | N3: =IF(E3="","NO_EXTRACT", IF(LOWER(TRIM(E3))=LOWER(TRIM(D3)),"MATCH","CHECK")) -> MATCH | O3: =IF(OR(K3="MISSING",L3="INVALID",M3="INVALID"),"ERROR","OK") -> OK | P3: =(K3="MISSING")*1 + (L3="INVALID")*1 + (M3="INVALID")*1 -> 0 | Q3: =YEAR(J3) & "-" & TEXT(MONTH(J3),"00") -> 2023-11 | R3: Planon | S3: =IF(tblChecks[[#This Row],[AnyError]]="ERROR",1,0) -> 0 | T3: =IF(tblChecks[[#This Row],[MissingStreet]]="MISSING",1,0) -> 0 | U3: =IF(K3="MISSING","MissingStreet", IF(L3="INVALID","PostalCode_INVALID", IF(M3="INVALID","Phone_INVALID","OK"))) -> OK
A4: =CleanedData!F4 -> PROP00003 | B4: =CleanedData!A4 -> UKLeeds, UK | C4: =CleanedData!D4 -> UK | D4: =CleanedData!E4 -> Leeds | E4: =CleanedData!O4 -> Leeds | F4: =CleanedData!M4 -> UK | G4: =CleanedData!B4 -> 4406 | H4: =CleanedData!C4 -> +9-597990383 | I4: =CleanedData!G4 -> Inactive | J4: =CleanedData!H4 -> 45259 | K4: =IF(TRIM(F4)="","MISSING","OK") -> OK | L4: =IF(LEN(TRIM(G4))<3,"INVALID","OK") -> OK | M4: =IF(LEN(SUBSTITUTE(SUBSTITUTE(H4," ",""),"-",""))>=7,"OK","INVALID") -> OK | N4: =IF(E4="","NO_EXTRACT", IF(LOWER(TRIM(E4))=LOWER(TRIM(D4)),"MATCH","CHECK")) -> MATCH | O4: =IF(OR(K4="MISSING",L4="INVALID",M4="INVALID"),"ERROR","OK") -> OK | P4: =(K4="MISSING")*1 + (L4="INVALID")*1 + (M4="INVALID")*1 -> 0 | Q4: =YEAR(J4) & "-" & TEXT(MONTH(J4),"00") -> 2023-11 | R4: Planon | S4: =IF(tblChecks[[#This Row],[AnyError]]="ERROR",1,0) -> 0 | T4: =IF(tblChecks[[#This Row],[MissingStreet]]="MISSING",1,0) -> 0 | U4: =IF(K4="MISSING","MissingStreet", IF(L4="INVALID","PostalCode_INVALID", IF(M4="INVALID","Phone_INVALID","OK"))) -> OK
A5: =CleanedData!F5 -> PROP00004 | B5: =CleanedData!A5 -> ToulouseJeffery Parkways231, France | C5: =CleanedData!D5 -> France | D5: =CleanedData!E5 -> Toulouse | E5: =CleanedData!O5 -> Toulouse | F5: =CleanedData!M5 -> ToulouseJeffery Parkways231 | G5: =CleanedData!B5 -> 79408 | H5: =CleanedData!C5 -> +41-562032557 | I5: =CleanedData!G5 -> Inactive | J5: =CleanedData!H5 -> 45406 | K5: =IF(TRIM(F5)="","MISSING","OK") -> OK | L5: =IF(LEN(TRIM(G5))<3,"INVALID","OK") -> OK | M5: =IF(LEN(SUBSTITUTE(SUBSTITUTE(H5," ",""),"-",""))>=7,"OK","INVALID") -> OK | N5: =IF(E5="","NO_EXTRACT", IF(LOWER(TRIM(E5))=LOWER(TRIM(D5)),"MATCH","CHECK")) -> MATCH | O5: =IF(OR(K5="MISSING",L5="INVALID",M5="INVALID"),"ERROR","OK") -> OK | P5: =(K5="MISSING")*1 + (L5="INVALID")*1 + (M5="INVALID")*1 -> 0 | Q5: =YEAR(J5) & "-" & TEXT(MONTH(J5),"00") -> 2024-04 | R5: MDG | S5: =IF(tblChecks[[#This Row],[AnyError]]="ERROR",1,0) -> 0 | T5: =IF(tblChecks[[#This Row],[MissingStreet]]="MISSING",1,0) -> 0 | U5: =IF(K5="MISSING","MissingStreet", IF(L5="INVALID","PostalCode_INVALID", IF(M5="INVALID","Phone_INVALID","OK"))) -> OK
A6: =CleanedData!F6 -> PROP00005 | B6: =CleanedData!A6 -> AdelaideAnna Stravenue73, Australia | C6: =CleanedData!D6 -> Australia | D6: =CleanedData!E6 -> Adelaide | E6: =CleanedData!O6 -> Adelaide | F6: =CleanedData!M6 -> AdelaideAnna Stravenue73 | G6: =CleanedData!B6 -> 85682 | H6: =CleanedData!C6 -> +58-662081724 | I6: =CleanedData!G6 -> Active | J6: =CleanedData!H6 -> 44973 | K6: =IF(TRIM(F6)="","MISSING","OK") -> OK | L6: =IF(LEN(TRIM(G6))<3,"INVALID","OK") -> OK | M6: =IF(LEN(SUBSTITUTE(SUBSTITUTE(H6," ",""),"-",""))>=7,"OK","INVALID") -> OK | N6: =IF(E6="","NO_EXTRACT", IF(LOWER(TRIM(E6))=LOWER(TRIM(D6)),"MATCH","CHECK")) -> MATCH | O6: =IF(OR(K6="MISSING",L6="INVALID",M6="INVALID"),"ERROR","OK") -> OK | P6: =(K6="MISSING")*1 + (L6="INVALID")*1 + (M6="INVALID")*1 -> 0 | Q6: =YEAR(J6) & "-" & TEXT(MONTH(J6),"00") -> 2023-02 | R6: Salesforce | S6: =IF(tblChecks[[#This Row],[AnyError]]="ERROR",1,0) -> 0 | T6: =IF(tblChecks[[#This Row],[MissingStreet]]="MISSING",1,0) -> 0 | U6: =IF(K6="MISSING","MissingStreet", IF(L6="INVALID","PostalCode_INVALID", IF(M6="INVALID","Phone_INVALID","OK"))) -> OK
A7: =CleanedData!F7 -> PROP00006 | B7: =CleanedData!A7 -> USA, Phoenix | C7: =CleanedData!D7 -> USA | D7: =CleanedData!E7 -> Phoenix | E7: =CleanedData!O7 -> Phoenix | F7: =CleanedData!M7 -> Phoenix | G7: =CleanedData!B7 -> 36964 | H7: =CleanedData!C7 -> +75-783458296 | I7: =CleanedData!G7 -> Inactive | J7: =CleanedData!H7 -> 45086 | K7: =IF(TRIM(F7)="","MISSING","OK") -> OK | L7: =IF(LEN(TRIM(G7))<3,"INVALID","OK") -> OK | M7: =IF(LEN(SUBSTITUTE(SUBSTITUTE(H7," ",""),"-",""))>=7,"OK","INVALID") -> OK | N7: =IF(E7="","NO_EXTRACT", IF(LOWER(TRIM(E7))=LOWER(TRIM(D7)),"MATCH","CHECK")) -> MATCH | O7: =IF(OR(K7="MISSING",L7="INVALID",M7="INVALID"),"ERROR","OK") -> OK | P7: =(K7="MISSING")*1 + (L7="INVALID")*1 + (M7="INVALID")*1 -> 0 | Q7: =YEAR(J7) & "-" & TEXT(MONTH(J7),"00") -> 2023-06 | R7: Planon | S7: =IF(tblChecks[[#This Row],[AnyError]]="ERROR",1,0) -> 0 | T7: =IF(tblChecks[[#This Row],[MissingStreet]]="MISSING",1,0) -> 0 | U7: =IF(K7="MISSING","MissingStreet", IF(L7="INVALID","PostalCode_INVALID", IF(M7="INVALID","Phone_INVALID","OK"))) -> OK
A8: =CleanedData!F8 -> PROP00007 | B8: =CleanedData!A8 -> Katherine Estate 93, Germany, Cologne | C8: =CleanedData!D8 -> Germany | D8: =CleanedData!E8 -> Cologne | E8: =CleanedData!O8 -> Cologne | F8: =CleanedData!M8 -> Katherine Estate 93 | G8: =CleanedData!B8 -> 92007 | H8: =CleanedData!C8 -> +24-457327975 | I8: =CleanedData!G8 -> Active | J8: =CleanedData!H8 -> 45240 | K8: =IF(TRIM(F8)="","MISSING","OK") -> OK | L8: =IF(LEN(TRIM(G8))<3,"INVALID","OK") -> OK | M8: =IF(LEN(SUBSTITUTE(SUBSTITUTE(H8," ",""),"-",""))>=7,"OK","INVALID") -> OK | N8: =IF(E8="","NO_EXTRACT", IF(LOWER(TRIM(E8))=LOWER(TRIM(D8)),"MATCH","CHECK")) -> MATCH | O8: =IF(OR(K8="MISSING",L8="INVALID",M8="INVALID"),"ERROR","OK") -> OK | P8: =(K8="MISSING")*1 + (L8="INVALID")*1 + (M8="INVALID")*1 -> 0 | Q8: =YEAR(J8) & "-" & TEXT(MONTH(J8),"00") -> 2023-11 | R8: ServiceNow | S8: =IF(tblChecks[[#This Row],[AnyError]]="ERROR",1,0) -> 0 | T8: =IF(tblChecks[[#This Row],[MissingStreet]]="MISSING",1,0) -> 0 | U8: =IF(K8="MISSING","MissingStreet", IF(L8="INVALID","PostalCode_INVALID", IF(M8="INVALID","Phone_INVALID","OK"))) -> OK
A9: =CleanedData!F9 -> PROP00008 | B9: =CleanedData!A9 -> Peterson Drives 204, Germany, Cologne | C9: =CleanedData!D9 -> Germany | D9: =CleanedData!E9 -> Cologne | E9: =CleanedData!O9 -> Cologne | F9: =CleanedData!M9 -> Peterson Drives 204 | G9: =CleanedData!B9 -> 28722 | H9: =CleanedData!C9 -> +49-576610421 | I9: =CleanedData!G9 -> Active | J9: =CleanedData!H9 -> 44972 | K9: =IF(TRIM(F9)="","MISSING","OK") -> OK | L9: =IF(LEN(TRIM(G9))<3,"INVALID","OK") -> OK | M9: =IF(LEN(SUBSTITUTE(SUBSTITUTE(H9," ",""),"-",""))>=7,"OK","INVALID") -> OK | N9: =IF(E9="","NO_EXTRACT", IF(LOWER(TRIM(E9))=LOWER(TRIM(D9)),"MATCH","CHECK")) -> MATCH | O9: =IF(OR(K9="MISSING",L9="INVALID",M9="INVALID"),"ERROR","OK") -> OK | P9: =(K9="MISSING")*1 + (L9="INVALID")*1 + (M9="INVALID")*1 -> 0 | Q9: =YEAR(J9) & "-" & TEXT(MONTH(J9),"00") -> 2023-02 | R9: SAP | S9: =IF(tblChecks[[#This Row],[AnyError]]="ERROR",1,0) -> 0 | T9: =IF(tblChecks[[#This Row],[MissingStreet]]="MISSING",1,0) -> 0 | U9: =IF(K9="MISSING","MissingStreet", IF(L9="INVALID","PostalCode_INVALID", IF(M9="INVALID","Phone_INVALID","OK"))) -> OK
A10: =CleanedData!F10 -> PROP00009 | B10: =CleanedData!A10 -> SpainBarcelona, Spain | C10: =CleanedData!D10 -> Spain | D10: =CleanedData!E10 -> Barcelona | E10: =CleanedData!O10 -> Barcelona | F10: =CleanedData!M10 -> Spain | G10: =CleanedData!B10 -> 13177 | H10: =CleanedData!C10 -> +34-805788258 | I10: =CleanedData!G10 -> Inactive | J10: =CleanedData!H10 -> 45573 | K10: =IF(TRIM(F10)="","MISSING","OK") -> OK | L10: =IF(LEN(TRIM(G10))<3,"INVALID","OK") -> OK | M10: =IF(LEN(SUBSTITUTE(SUBSTITUTE(H10," ",""),"-",""))>=7,"OK","INVALID") -> OK | N10: =IF(E10="","NO_EXTRACT", IF(LOWER(TRIM(E10))=LOWER(TRIM(D10)),"MATCH","CHECK")) -> MATCH | O10: =IF(OR(K10="MISSING",L10="INVALID",M10="INVALID"),"ERROR","OK") -> OK | P10: =(K10="MISSING")*1 + (L10="INVALID")*1 + (M10="INVALID")*1 -> 0 | Q10: =YEAR(J10) & "-" & TEXT(MONTH(J10),"00") -> 2024-10 | R10: SAP | S10: =IF(tblChecks[[#This Row],[AnyError]]="ERROR",1,0) -> 0 | T10: =IF(tblChecks[[#This Row],[MissingStreet]]="MISSING",1,0) -> 0 | U10: =IF(K10="MISSING","MissingStreet", IF(L10="INVALID","PostalCode_INVALID", IF(M10="INVALID","Phone_INVALID","OK"))) -> OK
A11: =CleanedData!F11 -> PROP00010 | B11: =CleanedData!A11 -> Abbott Rapids 298, Brazil, Brasília | C11: =CleanedData!D11 -> Brazil | D11: =CleanedData!E11 -> Brasília | E11: =CleanedData!O11 -> Brasília | F11: =CleanedData!M11 -> Abbott Rapids 298 | G11: =CleanedData!B11 -> 35172 | H11: =CleanedData!C11 -> +74-707015923 | I11: =CleanedData!G11 -> Active | J11: =CleanedData!H11 -> 45768 | K11: =IF(TRIM(F11)="","MISSING","OK") -> OK | L11: =IF(LEN(TRIM(G11))<3,"INVALID","OK") -> OK | M11: =IF(LEN(SUBSTITUTE(SUBSTITUTE(H11," ",""),"-",""))>=7,"OK","INVALID") -> OK | N11: =IF(E11="","NO_EXTRACT", IF(LOWER(TRIM(E11))=LOWER(TRIM(D11)),"MATCH","CHECK")) -> MATCH | O11: =IF(OR(K11="MISSING",L11="INVALID",M11="INVALID"),"ERROR","OK") -> OK | P11: =(K11="MISSING")*1 + (L11="INVALID")*1 + (M11="INVALID")*1 -> 0 | Q11: =YEAR(J11) & "-" & TEXT(MONTH(J11),"00") -> 2025-04 | R11: MDG | S11: =IF(tblChecks[[#This Row],[AnyError]]="ERROR",1,0) -> 0 | T11: =IF(tblChecks[[#This Row],[MissingStreet]]="MISSING",1,0) -> 0 | U11: =IF(K11="MISSING","MissingStreet", IF(L11="INVALID","PostalCode_INVALID", IF(M11="INVALID","Phone_INVALID","OK"))) -> OK
A12: =CleanedData!F12 -> PROP00011 | B12: =CleanedData!A12 -> Australia, Perth | C12: =CleanedData!D12 -> Australia | D12: =CleanedData!E12 -> Perth | E12: =CleanedData!O12 -> Perth | F12: =CleanedData!M12 -> Perth | G12: =CleanedData!B12 -> 16862 | H12: =CleanedData!C12 -> +19-563762604 | I12: =CleanedData!G12 -> Active | J12: =CleanedData!H12 -> 44924 | K12: =IF(TRIM(F12)="","MISSING","OK") -> OK | L12: =IF(LEN(TRIM(G12))<3,"INVALID","OK") -> OK | M12: =IF(LEN(SUBSTITUTE(SUBSTITUTE(H12," ",""),"-",""))>=7,"OK","INVALID") -> OK | N12: =IF(E12="","NO_EXTRACT", IF(LOWER(TRIM(E12))=LOWER(TRIM(D12)),"MATCH","CHECK")) -> MATCH | O12: =IF(OR(K12="MISSING",L12="INVALID",M12="INVALID"),"ERROR","OK") -> OK | P12: =(K12="MISSING")*1 + (L12="INVALID")*1 + (M12="INVALID")*1 -> 0 | Q12: =YEAR(J12) & "-" & TEXT(MONTH(J12),"00") -> 2022-12 | R12: SAP | S12: =IF(tblChecks[[#This Row],[AnyError]]="ERROR",1,0) -> 0 | T12: =IF(tblChecks[[#This Row],[MissingStreet]]="MISSING",1,0) -> 0 | U12: =IF(K12="MISSING","MissingStreet", IF(L12="INVALID","PostalCode_INVALID", IF(M12="INVALID","Phone_INVALID","OK"))) -> OK
A13: =CleanedData!F13 -> PROP00012 | B13: =CleanedData!A13 -> CanadaOttawa | C13: =CleanedData!D13 -> Canada | D13: =CleanedData!E13 -> Ottawa | E13: =CleanedData!O13 -> Ottawa | F13: =CleanedData!M13 | G13: =CleanedData!B13 -> 82898 | H13: =CleanedData!C13 -> +76-641811982 | I13: =CleanedData!G13 -> Active | J13: =CleanedData!H13 -> 45943 | K13: =IF(TRIM(F13)="","MISSING","OK") -> MISSING | L13: =IF(LEN(TRIM(G13))<3,"INVALID","OK") -> OK | M13: =IF(LEN(SUBSTITUTE(SUBSTITUTE(H13," ",""),"-",""))>=7,"OK","INVALID") -> OK | N13: =IF(E13="","NO_EXTRACT", IF(LOWER(TRIM(E13))=LOWER(TRIM(D13)),"MATCH","CHECK")) -> MATCH | O13: =IF(OR(K13="MISSING",L13="INVALID",M13="INVALID"),"ERROR","OK") -> ERROR | P13: =(K13="MISSING")*1 + (L13="INVALID")*1 + (M13="INVALID")*1 -> 1 | Q13: =YEAR(J13) & "-" & TEXT(MONTH(J13),"00") -> 2025-10 | R13: Salesforce | S13: =IF(tblChecks[[#This Row],[AnyError]]="ERROR",1,0) -> 1 | T13: =IF(tblChecks[[#This Row],[MissingStreet]]="MISSING",1,0) -> 1 | U13: =IF(K13="MISSING","MissingStreet", IF(L13="INVALID","PostalCode_INVALID", IF(M13="INVALID","Phone_INVALID","OK"))) -> MissingStreet
... A501: =CleanedData!F501 -> PROP00500 | B501: =CleanedData!A501 -> Montgomery Burgs146, Adelaide, Australia | C501: =CleanedData!D501 -> Australia | D501: =CleanedData!E501 -> Adelaide | E501: =CleanedData!O501 -> Adelaide | F501: =CleanedData!M501 -> Montgomery Burgs146 | G501: =CleanedData!B501 -> 65779 | H501: =CleanedData!C501 -> +21-283047445 | I501: =CleanedData!G501 -> Inactive | J501: =CleanedData!H501 -> 45625 | K501: =IF(TRIM(F501)="","MISSING","OK") -> OK | L501: =IF(LEN(TRIM(G501))<3,"INVALID","OK") -> OK | M501: =IF(LEN(SUBSTITUTE(SUBSTITUTE(H501," ",""),"-",""))>=7,"OK","INVALID") -> OK | N501: =IF(E501="","NO_EXTRACT", IF(LOWER(TRIM(E501))=LOWER(TRIM(D501)),"MATCH","CHECK")) -> MATCH | O501: =IF(OR(K501="MISSING",L501="INVALID",M501="INVALID"),"ERROR","OK") -> OK | P501: =(K501="MISSING")*1 + (L501="INVALID")*1 + (M501="INVALID")*1 -> 0 | Q501: =YEAR(J501) & "-" & TEXT(MONTH(J501),"00") -> 2024-11 | R501: Planon | S501: =IF(tblChecks[[#This Row],[AnyError]]="ERROR",1,0) -> 0 | T501: =IF(tblChecks[[#This Row],[MissingStreet]]="MISSING",1,0) -> 0 | U501: =IF(K501="MISSING","MissingStreet", IF(L501="INVALID","PostalCode_INVALID", IF(M501="INVALID","Phone_INVALID","OK"))) -> OK

Sheet ErrorsByCountry
A2: Row Labels | B2: Sum of IsError
A3: France | B3: 10
A4: Canada | B4: 10
A5: Australia | B5: 9
A6: Germany | B6: 9
A7: Italy | B7: 8
A8: UK | B8: 6
A9: Japan | B9: 6
A10: USA | B10: 5
A11: Spain | B11: 3
A12: Brazil | B12: 2
A13: Grand Total | B13: 68

Sheet TopErrorTypes
A2: Row Labels | B2: Count of ErrorType
A3: MissingStreet | B3: 68
A4: Grand Total | B4: 68

Sheet TrendErrorsByMonth
A2: Row Labels | B2: Sum of IsError
A3: 2022-11 | B3: 1
A4: 2022-12 | B4: 0
A5: 2023-01 | B5: 1
A6: 2023-02 | B6: 1
A7: 2023-03 | B7: 1
A8: 2023-04 | B8: 3
A9: 2023-05 | B9: 1
A10: 2023-06 | B10: 5
A11: 2023-07 | B11: 6
A12: 2023-08 | B12: 2
A13: 2023-09 | B13: 1
A14: 2023-10 | B14: 4
... A40: Grand Total | B40: 68

Sheet ErrorsByStatus
A2: Row Labels | B2: Count of AnyError
A3: Active | B3: 242
A4: Inactive | B4: 258
A5: Grand Total | B5: 500

Sheet Dashboard
